#VRML_SIM R2019a utf8
WorldInfo {
}
Viewpoint {
  orientation 0.9455974620720339 -0.3139482396625372 -0.0853342987064547 5.723381745177921
  position 0.3174339876935811 1.0427032103247273 1.4811867783134223
}
TexturedBackground {
}
TexturedBackgroundLight {
}
Floor {
}
Solid {
  translation 0 0.25 0
  children [
    Shape {
      appearance PBRAppearance {
        baseColor 0.3058823529411765 0.6039215686274509 0.023529411764705882
        roughness 1
        metalness 0
      }
      geometry Cylinder {
        height 0.5
        radius 0.05
      }
    }
    HingeJoint {
      jointParameters HingeJointParameters {
        axis 0 1 0
        anchor 0 0.255 0
        minStop -0.785
        maxStop 0.785
        staticFriction 0.01
      }
      endPoint Solid {
        translation 0 0.25489022123541294 0
        children [
          Shape {
            appearance PBRAppearance {
              baseColor 0.20392156862745098 0.396078431372549 0.6431372549019608
              roughness 1
              metalness 0
            }
            geometry Box {
              size 0.8 0.01 0.1
            }
          }
        ]
        physics Physics {
        }
      }
    }
    HingeJoint {
      jointParameters HingeJointParameters {
        axis 0 1 0
        anchor 0 0.055 0
      }
      endPoint Solid {
        translation 0 0 0.055
        children [
          Shape {
            appearance PBRAppearance {
              baseColor 0.4588235294117647 0.3137254901960784 0.4823529411764706
              roughness 1
              metalness 0
            }
            geometry Box {
              size 0.1 0.03 0.01
            }
          }
        ]
        name "solid(1)"
        physics Physics {
        }
      }
    }
  ]
}
