#VRML_SIM R2019a utf8
WorldInfo {
}
Viewpoint {
  orientation -0.5531351599544959 0.8255115045842613 0.1121260479154758 0.48158511624751055
  position 0.765678930610522 0.8352628791452694 1.5796884872199868
}
TexturedBackground {
}
TexturedBackgroundLight {
}
Floor {
}
Solid {
  translation 0 0.25 0
  children [
    Shape {
      appearance PBRAppearance {
        baseColor 0.3058823529411765 0.6039215686274509 0.023529411764705882
        roughness 1
        metalness 0
      }
      geometry Cylinder {
        height 0.5
        radius 0.05
      }
    }
    HingeJoint {
      jointParameters HingeJointParameters {
        axis 0 1 0
        anchor 0 0.255 0
        staticFriction 0.01
      }
      endPoint Solid {
        translation 0 0.25489022123541294 0
        children [
          Shape {
            appearance PBRAppearance {
              baseColor 0.20392156862745098 0.396078431372549 0.6431372549019608
              roughness 1
              metalness 0
            }
            geometry Box {
              size 0.8 0.01 0.1
            }
          }
        ]
        physics Physics {
        }
      }
    }
  ]
}
